Workbook
Name CLadrs: [1]!THZBD25[[#All],[ADRESSE]]
Name CLadrs: [1]!THZBD25[[#All],[ADRESSE]]
Name Clards1: [1]!THZBD25[[#All],[ADRESSE]]
Name Clards1: [1]!THZBD25[[#All],[ADRESSE]]
Name CLclss: [1]!THZBD25[[#All],[ClASSE]]
Name CLclss: [1]!THZBD25[[#All],[ClASSE]]
Name CLct: [1]!THZBD25[[#All],[CATEGORIE]]
Name CLct: [1]!THZBD25[[#All],[CATEGORIE]]
Name CLdt: [1]!THZBD25[[#All],[DATE]]
Name CLdt: [1]!THZBD25[[#All],[DATE]]
Name CLff: [1]!THZBD25[[#Headers],[FF]]
Name CLff: [1]!THZBD25[[#Headers],[FF]]
Name CLfip: [1]!THZBD25[[#All],[FIP]]
Name CLfip: [1]!THZBD25[[#All],[FIP]]
Name CLjrs: [1]!THZBD25[[#All],[JOUR]]
Name CLjrs: [1]!THZBD25[[#All],[JOUR]]
Name CLldtnss: [1]!THZBD25[[#All],[Lieu et DNSS]]
Name CLldtnss: [1]!THZBD25[[#All],[Lieu et DNSS]]
Name CLmat: [1]!THZBD25[[#All],[MAT]]
Name CLmat: [1]!THZBD25[[#All],[MAT]]
Name CLmois: [1]!THZBD25[[#All],[MOIS]]
Name CLmois: [1]!THZBD25[[#All],[MOIS]]
Name CLnmRec: [1]!THZBD25[[#All],[NUM RECU]]
Name CLnmRec: [1]!THZBD25[[#All],[NUM RECU]]
Name CLnom: [1]!THZBD25[[#All],[NOM ]]
Name CLnom: [1]!THZBD25[[#All],[NOM ]]
Name CLobs: [1]!THZBD25[[#All],[OBS]]
Name CLobs: [1]!THZBD25[[#All],[OBS]]
Name CLresp: [1]!THZBD25[[#All],[RESPO & Fonction]]
Name CLresp: [1]!THZBD25[[#All],[RESPO & Fonction]]
Name CLSect: [1]!THZBD25[[#All],[SECTION]]
Name CLSect: [1]!THZBD25[[#All],[SECTION]]
Name CLsex: [1]!THZBD25[[#All],[SEXE]]
Name CLsex: [1]!THZBD25[[#All],[SEXE]]
Name CLtel: [1]!THZBD25[[#All],[TELEPHONE]]
Name CLtel: [1]!THZBD25[[#All],[TELEPHONE]]
Name ELIECORRECTION: [1]!THZBD25[[#All],[ClASSE]]
Name ELIECORRECTION: [1]!THZBD25[[#All],[ClASSE]]
Name LisrClasse: [1]PARAMETTRE!$P$6:$P$44
Name ListAdress2024: [1]THZBD24!$N$8:$N$3070
Name ListBD: 'BDFIP2526 (2)'!$D$9:$S$993
Name ListBD: [1]BESS!$D$11:$P$1427
Name ListCat2024: [1]THZBD24!$F$9:$F$3070
Name ListCateg2023: [1]!TBCategorie[CATEGORIE]
Name ListCateg2023: [1]!TBCategorie[CATEGORIE]
Name ListID: [1]!TBID[ID]
Name ListID: [1]!TBID[ID]
Name ListMat: [0]!ListBD:[0]!LisrClasse
Name ListMat: ListBD:LisrClasse
Name ListMATR: [1]THZBD24!$B$8:$B$3070
Name ListMois: [1]!TBMois[MOIS]
Name ListMois: [1]!TBMois[MOIS]
Name ListMont: [1]PARAMETTRE!$L$6,[1]PARAMETTRE!$L$25228
Name ListNMR: [0]!ListCat2024:[0]!ListAdress2024
Name ListNMR: ListCat2024:ListAdress2024
Name ListNom: 'BDFIP2526 (2)'!ListCateg2023:'BDFIP2526 (2)'!ListBD
Name ListNom: #N/A
Name ListNomInscr2024: [1]THZBD24!$G$9:$G$3070
Name ListSection: [1]!TBSection[SECTION]
Name ListSection: [1]!TBSection[SECTION]

Sheet BDFIP2526 (2)
J6: MONTANT | M6: J SEMAINE | U6: 3M | W6: Dec | AN6: RECHERCHE | AO6: TSHITENGE BANTU SETU
B8: Num | C8: Matricule | D8: Nom | E8: NumRecu | F8: Sexe | G8: Classe | H8: Categorie | I8: Mois | J8: FIP | K8: FF | L8: Obs | M8: Jour | N8: DatePaiement | O8: AnneeScolaire | P8: Section | Q8: Telephone | R8: Email
B9: 1 | C9: PL652 | D9: LUMPUNGU LUMPIBWE | E9: 6672 | F9: M | G9: 1°Cons | H9: PY | I9: Sept | J9: 55 | L9: N | M9: SAMED | N9: 45934 | O9: 2025-2026 | P9: SEC | X9: 45896.651 | AS9: 45236.128 | AU9: 45172.044
B10: 2 | C10: PL541 | D10: NEHEMA KAZADI | E10: 6503 | F10: F | G10: 2°Lit | H10: PY | I10: Ac.Sept | J10: 20 | L10: A | M10: JEUD | N10: 45876 | O10: 2025-2026 | P10: SEC | AS10: CLASSE | AT10: SEXE | AU10: DAYE | AV10: JOUR | AW10: NUM RECU | AX10: MOIS | AY10: FIP | AZ10: FF | BA10: N°
B11: 3 | C11: PL308 | D11: ODIMBA WA OKUNDJI | E11: 6882 | F11: M | G11: 4°HP | H11: PY | I11: Oct | J11: 80 | L11: A | N11: 45879 | O11: 25-26 | P11: SEC | Q11: 993138694 | AQ11: 0
B12: 4 | C12: PL301 | D12: TEKELA NZEWU | E12: 6505 | F12: F | G12: 2°Lit | H12: PY | I12: Sept | J12: 45 | L12: A | M12: MARD | N12: 45881 | O12: 25-26 | P12: SEC | AM12: {=INDEX('BDFIP2526 (2)'!$N$9:$N$1229,SMALL(IF($AO$6='BDFIP2526 (2)'!$D$9:$D$1229,ROW('BDFIP2526 (2)'!$D$9:$D$1229)-MIN(ROW($D$9))+1,""),1))} -> #NUM! | AN12: {=INDEX('BDFIP2526 (2)'!#REF!,SMALL(IF($AO$6='BDFIP2526 (2)'!$D$9:$D$1229,ROW('BDFIP2526 (2)'!$D$9:$D$1229)-MIN(ROW($D$9))+1,""),1))} -> #REF! | AO12: {=INDEX(#REF!,SMALL(IF($AO$6='BDFIP2526 (2)'!$D$9:$D$1229,ROW('BDFIP2526 (2)'!$D$9:$D$1229)-MIN(ROW($D$9))+1,""),1))} -> #REF! | AQ12: 2 | AT12: =IFERROR(INDEX('BDFIP2526 (2)'!$F$9:$F$1229,SMALL(IF($AO$6='BDFIP2526 (2)'!$D$9:$D$1229,ROW('BDFIP2526 (2)'!$D$9:$D$1229)-MIN(ROW($D$9))+1,""),ROWS(AT$12:AT12))),"") | AU12: {=IFERROR(INDEX('BDFIP2526 (2)'!$N$9:$N$1229,SMALL(IF($AO$6='BDFIP2526 (2)'!$D$9:$D$1229,ROW('BDFIP2526 (2)'!$D$9:$D$1229)-MIN(ROW($D$9))+1,""),ROWS(AU$12:AU12))),"")} | AV12: {=IFERROR(INDEX('BDFIP2526 (2)'!$M$9:$M$1229,SMALL(IF($AO$6='BDFIP2526 (2)'!$D$9:$D$1229,ROW('BDFIP2526 (2)'!$D$9:$D$1229)-MIN(ROW($D$9))+1,""),ROWS(AV$12:AV12))),"")} | AW12: {=IFERROR(INDEX('BDFIP2526 (2)'!$E$9:$E$1229,SMALL(IF($AO$6='BDFIP2526 (2)'!$D$9:$D$1229,ROW('BDFIP2526 (2)'!$D$9:$D$1229)-MIN(ROW($D$9))+1,""),ROWS(AW$12:AW12))),"")} | AX12: {=IFERROR(INDEX('BDFIP2526 (2)'!#REF!,SMALL(IF($AO$6='BDFIP2526 (2)'!$D$9:$D$1229,ROW('BDFIP2526 (2)'!$D$9:$D$1229)-MIN(ROW($D$9))+1,""),ROWS(AX$12:AX12))),"")} | AY12: {=IFERROR(INDEX('BDFIP2526 (2)'!$J$9:$J$1229,SMALL(IF($AO$6='BDFIP2526 (2)'!$D$9:$D$1229,ROW('BDFIP2526 (2)'!$D$9:$D$1229)-MIN(ROW($D$9))+1,""),ROWS(AY$12:AY12))),"")} | AZ12: {=IFERROR(INDEX('BDFIP2526 (2)'!$K$9:$K$1229,SMALL(IF($AO$6='BDFIP2526 (2)'!$D$9:$D$1229,ROW('BDFIP2526 (2)'!$D$9:$D$1229)-MIN(ROW($D$9))+1,""),ROWS(AZ$12:AZ12))),"")} | BA12: {=IFERROR(INDEX(#REF!,SMALL(IF($AO$6='BDFIP2526 (2)'!$D$9:$D$1229,ROW('BDFIP2526 (2)'!$D$9:$D$1229)-MIN(ROW($D$9))+1,""),ROWS(BA$12:BA12))),"")}
B13: 5 | C13: PL300 | D13: NGALULA NZEWU | E13: 6504 | F13: F | G13: 3°Sc | H13: PY | I13: Sept | J13: 80 | L13: A | M13: MARD | N13: 45881 | O13: 25-26 | P13: SEC | AM13: {=INDEX('BDFIP2526 (2)'!$N$9:$N$1229,SMALL(IF($AO$6='BDFIP2526 (2)'!$D$9:$D$1229,ROW('BDFIP2526 (2)'!$D$9:$D$1229)-MIN(ROW($D$9))+1,""),2))} -> #NUM! | AN13: {=INDEX('BDFIP2526 (2)'!#REF!,SMALL(IF($AO$6='BDFIP2526 (2)'!$D$9:$D$1229,ROW('BDFIP2526 (2)'!$D$9:$D$1229)-MIN(ROW($D$9))+1,""),2))} -> #REF! | AO13: {=INDEX(#REF!,SMALL(IF($AO$6='BDFIP2526 (2)'!$D$9:$D$1229,ROW('BDFIP2526 (2)'!$D$9:$D$1229)-MIN(ROW($D$9))+1,""),2))} -> #REF! | AQ13: 6 | AS13: {=IFERROR(INDEX('BDFIP2526 (2)'!$G$9:$G$1229,SMALL(IF($AO$6='BDFIP2526 (2)'!$D$9:$D$1229,ROW('BDFIP2526 (2)'!$D$9:$D$1229)-MIN(ROW($D$9))+1,""),ROWS(AS$12:AS13))),"")} | AT13: {=IFERROR(INDEX('BDFIP2526 (2)'!$F$9:$F$1229,SMALL(IF($AO$6='BDFIP2526 (2)'!$D$9:$D$1229,ROW('BDFIP2526 (2)'!$D$9:$D$1229)-MIN(ROW($D$9))+1,""),ROWS(AT$12:AT13))),"")} | AU13: {=IFERROR(INDEX('BDFIP2526 (2)'!$N$9:$N$1229,SMALL(IF($AO$6='BDFIP2526 (2)'!$D$9:$D$1229,ROW('BDFIP2526 (2)'!$D$9:$D$1229)-MIN(ROW($D$9))+1,""),ROWS(AU$12:AU13))),"")} | AV13: {=IFERROR(INDEX('BDFIP2526 (2)'!$M$9:$M$1229,SMALL(IF($AO$6='BDFIP2526 (2)'!$D$9:$D$1229,ROW('BDFIP2526 (2)'!$D$9:$D$1229)-MIN(ROW($D$9))+1,""),ROWS(AV$12:AV13))),"")} | AW13: {=IFERROR(INDEX('BDFIP2526 (2)'!$E$9:$E$1229,SMALL(IF($AO$6='BDFIP2526 (2)'!$D$9:$D$1229,ROW('BDFIP2526 (2)'!$D$9:$D$1229)-MIN(ROW($D$9))+1,""),ROWS(AW$12:AW13))),"")} | AX13: {=IFERROR(INDEX('BDFIP2526 (2)'!#REF!,SMALL(IF($AO$6='BDFIP2526 (2)'!$D$9:$D$1229,ROW('BDFIP2526 (2)'!$D$9:$D$1229)-MIN(ROW($D$9))+1,""),ROWS(AX$12:AX13))),"")} | AY13: {=IFERROR(INDEX('BDFIP2526 (2)'!$J$9:$J$1229,SMALL(IF($AO$6='BDFIP2526 (2)'!$D$9:$D$1229,ROW('BDFIP2526 (2)'!$D$9:$D$1229)-MIN(ROW($D$9))+1,""),ROWS(AY$12:AY13))),"")} | AZ13: {=IFERROR(INDEX('BDFIP2526 (2)'!$K$9:$K$1229,SMALL(IF($AO$6='BDFIP2526 (2)'!$D$9:$D$1229,ROW('BDFIP2526 (2)'!$D$9:$D$1229)-MIN(ROW($D$9))+1,""),ROWS(AZ$12:AZ13))),"")} | BA13: {=IFERROR(INDEX(#REF!,SMALL(IF($AO$6='BDFIP2526 (2)'!$D$9:$D$1229,ROW('BDFIP2526 (2)'!$D$9:$D$1229)-MIN(ROW($D$9))+1,""),ROWS(BA$12:BA13))),"")}
B14: 6 | C14: LT545 | D14: MAKOLO MWAMBA | E14: 6510 | F14: F | G14: 3M | H14: PY | I14: Aout | J14: 40 | L14: N | M14: VEND | N14: 45891 | O14: 2025-2026 | P14: MAT | Q14: 814533261 | AM14: {=INDEX('BDFIP2526 (2)'!$N$9:$N$1229,SMALL(IF($AO$6='BDFIP2526 (2)'!$D$9:$D$1229,ROW('BDFIP2526 (2)'!$D$9:$D$1229)-MIN(ROW($D$9))+1,""),3))} -> #NUM! | AN14: {=INDEX('BDFIP2526 (2)'!#REF!,SMALL(IF($AO$6='BDFIP2526 (2)'!$D$9:$D$1229,ROW('BDFIP2526 (2)'!$D$9:$D$1229)-MIN(ROW($D$9))+1,""),3))} -> #REF! | AO14: {=INDEX(#REF!,SMALL(IF($AO$6='BDFIP2526 (2)'!$D$9:$D$1229,ROW('BDFIP2526 (2)'!$D$9:$D$1229)-MIN(ROW($D$9))+1,""),3))} -> #REF! | AQ14: 9 | AS14: {=IFERROR(INDEX('BDFIP2526 (2)'!$G$9:$G$1229,SMALL(IF($AO$6='BDFIP2526 (2)'!$D$9:$D$1229,ROW('BDFIP2526 (2)'!$D$9:$D$1229)-MIN(ROW($D$9))+1,""),ROWS(AS$12:AS14))),"")} | AT14: {=IFERROR(INDEX('BDFIP2526 (2)'!$F$9:$F$1229,SMALL(IF($AO$6='BDFIP2526 (2)'!$D$9:$D$1229,ROW('BDFIP2526 (2)'!$D$9:$D$1229)-MIN(ROW($D$9))+1,""),ROWS(AT$12:AT14))),"")} | AU14: {=IFERROR(INDEX('BDFIP2526 (2)'!$N$9:$N$1229,SMALL(IF($AO$6='BDFIP2526 (2)'!$D$9:$D$1229,ROW('BDFIP2526 (2)'!$D$9:$D$1229)-MIN(ROW($D$9))+1,""),ROWS(AU$12:AU14))),"")} | AV14: {=IFERROR(INDEX('BDFIP2526 (2)'!$M$9:$M$1229,SMALL(IF($AO$6='BDFIP2526 (2)'!$D$9:$D$1229,ROW('BDFIP2526 (2)'!$D$9:$D$1229)-MIN(ROW($D$9))+1,""),ROWS(AV$12:AV14))),"")} | AW14: {=IFERROR(INDEX('BDFIP2526 (2)'!$E$9:$E$1229,SMALL(IF($AO$6='BDFIP2526 (2)'!$D$9:$D$1229,ROW('BDFIP2526 (2)'!$D$9:$D$1229)-MIN(ROW($D$9))+1,""),ROWS(AW$12:AW14))),"")} | AX14: {=IFERROR(INDEX('BDFIP2526 (2)'!#REF!,SMALL(IF($AO$6='BDFIP2526 (2)'!$D$9:$D$1229,ROW('BDFIP2526 (2)'!$D$9:$D$1229)-MIN(ROW($D$9))+1,""),ROWS(AX$12:AX14))),"")} | AY14: {=IFERROR(INDEX('BDFIP2526 (2)'!$J$9:$J$1229,SMALL(IF($AO$6='BDFIP2526 (2)'!$D$9:$D$1229,ROW('BDFIP2526 (2)'!$D$9:$D$1229)-MIN(ROW($D$9))+1,""),ROWS(AY$12:AY14))),"")} | AZ14: {=IFERROR(INDEX('BDFIP2526 (2)'!$K$9:$K$1229,SMALL(IF($AO$6='BDFIP2526 (2)'!$D$9:$D$1229,ROW('BDFIP2526 (2)'!$D$9:$D$1229)-MIN(ROW($D$9))+1,""),ROWS(AZ$12:AZ14))),"")} | BA14: {=IFERROR(INDEX(#REF!,SMALL(IF($AO$6='BDFIP2526 (2)'!$D$9:$D$1229,ROW('BDFIP2526 (2)'!$D$9:$D$1229)-MIN(ROW($D$9))+1,""),ROWS(BA$12:BA14))),"")}
B15: 7 | C15: PL303 | D15: NUMBI KAMWANYA | E15: 6511 | F15: F | G15: 2°TCC | H15: PY | I15: Aout | J15: 55 | L15: A | M15: MARD | N15: 45895 | O15: 2025-2026 | P15: SEC | Q15: 0858913202/0998525070 | AM15: {=INDEX('BDFIP2526 (2)'!$N$9:$N$1229,SMALL(IF(AO10='BDFIP2526 (2)'!$D$9:$D$1229,ROW('BDFIP2526 (2)'!$D$9:$D$1229)-MIN(ROW($D$9))+1,""),10))} -> #NUM! | AQ15: 3 | AS15: {=IFERROR(INDEX('BDFIP2526 (2)'!$G$9:$G$1229,SMALL(IF($AO$6='BDFIP2526 (2)'!$D$9:$D$1229,ROW('BDFIP2526 (2)'!$D$9:$D$1229)-MIN(ROW($D$9))+1,""),ROWS(AS$12:AS15))),"")} | AT15: {=IFERROR(INDEX('BDFIP2526 (2)'!$F$9:$F$1229,SMALL(IF($AO$6='BDFIP2526 (2)'!$D$9:$D$1229,ROW('BDFIP2526 (2)'!$D$9:$D$1229)-MIN(ROW($D$9))+1,""),ROWS(AT$12:AT15))),"")} | AU15: {=IFERROR(INDEX('BDFIP2526 (2)'!$N$9:$N$1229,SMALL(IF($AO$6='BDFIP2526 (2)'!$D$9:$D$1229,ROW('BDFIP2526 (2)'!$D$9:$D$1229)-MIN(ROW($D$9))+1,""),ROWS(AU$12:AU15))),"")} | AV15: {=IFERROR(INDEX('BDFIP2526 (2)'!$M$9:$M$1229,SMALL(IF($AO$6='BDFIP2526 (2)'!$D$9:$D$1229,ROW('BDFIP2526 (2)'!$D$9:$D$1229)-MIN(ROW($D$9))+1,""),ROWS(AV$12:AV15))),"")} | AW15: {=IFERROR(INDEX('BDFIP2526 (2)'!$E$9:$E$1229,SMALL(IF($AO$6='BDFIP2526 (2)'!$D$9:$D$1229,ROW('BDFIP2526 (2)'!$D$9:$D$1229)-MIN(ROW($D$9))+1,""),ROWS(AW$12:AW15))),"")} | AX15: {=IFERROR(INDEX('BDFIP2526 (2)'!#REF!,SMALL(IF($AO$6='BDFIP2526 (2)'!$D$9:$D$1229,ROW('BDFIP2526 (2)'!$D$9:$D$1229)-MIN(ROW($D$9))+1,""),ROWS(AX$12:AX15))),"")} | AY15: {=IFERROR(INDEX('BDFIP2526 (2)'!$J$9:$J$1229,SMALL(IF($AO$6='BDFIP2526 (2)'!$D$9:$D$1229,ROW('BDFIP2526 (2)'!$D$9:$D$1229)-MIN(ROW($D$9))+1,""),ROWS(AY$12:AY15))),"")} | AZ15: {=IFERROR(INDEX('BDFIP2526 (2)'!$K$9:$K$1229,SMALL(IF($AO$6='BDFIP2526 (2)'!$D$9:$D$1229,ROW('BDFIP2526 (2)'!$D$9:$D$1229)-MIN(ROW($D$9))+1,""),ROWS(AZ$12:AZ15))),"")} | BA15: {=IFERROR(INDEX(#REF!,SMALL(IF($AO$6='BDFIP2526 (2)'!$D$9:$D$1229,ROW('BDFIP2526 (2)'!$D$9:$D$1229)-MIN(ROW($D$9))+1,""),ROWS(BA$12:BA15))),"")}
B16: 8 | C16: PL342 | D16: KISIMBA BENDERA ILUNGA | E16: 6512 | F16: F | G16: 8°EB | H16: PY | I16: Aout | J16: 45 | L16: A | M16: VEND | N16: 45898 | O16: 2025-2026 | P16: SEC | Q16: 0850932909/0990262434 | AQ16: 1 | AS16: {=IFERROR(INDEX('BDFIP2526 (2)'!$G$9:$G$1229,SMALL(IF($AO$6='BDFIP2526 (2)'!$D$9:$D$1229,ROW('BDFIP2526 (2)'!$D$9:$D$1229)-MIN(ROW($D$9))+1,""),ROWS(AS$12:AS16))),"")} | AT16: {=IFERROR(INDEX('BDFIP2526 (2)'!$F$9:$F$1229,SMALL(IF($AO$6='BDFIP2526 (2)'!$D$9:$D$1229,ROW('BDFIP2526 (2)'!$D$9:$D$1229)-MIN(ROW($D$9))+1,""),ROWS(AT$12:AT16))),"")} | AU16: {=IFERROR(INDEX('BDFIP2526 (2)'!$N$9:$N$1229,SMALL(IF($AO$6='BDFIP2526 (2)'!$D$9:$D$1229,ROW('BDFIP2526 (2)'!$D$9:$D$1229)-MIN(ROW($D$9))+1,""),ROWS(AU$12:AU16))),"")} | AV16: {=IFERROR(INDEX('BDFIP2526 (2)'!$M$9:$M$1229,SMALL(IF($AO$6='BDFIP2526 (2)'!$D$9:$D$1229,ROW('BDFIP2526 (2)'!$D$9:$D$1229)-MIN(ROW($D$9))+1,""),ROWS(AV$12:AV16))),"")} | AW16: {=IFERROR(INDEX('BDFIP2526 (2)'!$E$9:$E$1229,SMALL(IF($AO$6='BDFIP2526 (2)'!$D$9:$D$1229,ROW('BDFIP2526 (2)'!$D$9:$D$1229)-MIN(ROW($D$9))+1,""),ROWS(AW$12:AW16))),"")} | AX16: {=IFERROR(INDEX('BDFIP2526 (2)'!#REF!,SMALL(IF($AO$6='BDFIP2526 (2)'!$D$9:$D$1229,ROW('BDFIP2526 (2)'!$D$9:$D$1229)-MIN(ROW($D$9))+1,""),ROWS(AX$12:AX16))),"")} | AY16: {=IFERROR(INDEX('BDFIP2526 (2)'!$J$9:$J$1229,SMALL(IF($AO$6='BDFIP2526 (2)'!$D$9:$D$1229,ROW('BDFIP2526 (2)'!$D$9:$D$1229)-MIN(ROW($D$9))+1,""),ROWS(AY$12:AY16))),"")} | AZ16: {=IFERROR(INDEX('BDFIP2526 (2)'!$K$9:$K$1229,SMALL(IF($AO$6='BDFIP2526 (2)'!$D$9:$D$1229,ROW('BDFIP2526 (2)'!$D$9:$D$1229)-MIN(ROW($D$9))+1,""),ROWS(AZ$12:AZ16))),"")} | BA16: {=IFERROR(INDEX(#REF!,SMALL(IF($AO$6='BDFIP2526 (2)'!$D$9:$D$1229,ROW('BDFIP2526 (2)'!$D$9:$D$1229)-MIN(ROW($D$9))+1,""),ROWS(BA$12:BA16))),"")}
B17: 9 | C17: PL121 | D17: NGENDA KADIMA | E17: 6517 | F17: F | G17: 2°HP | H17: PY | I17: Aout | J17: 45 | L17: N | M17: VEND | N17: 45898 | O17: 2025-2026 | P17: SEC | Q17: 977415665 | AO17: =SMALL($AQ$11:$AQ$16,1) -> 0 | AS17: {=IFERROR(INDEX('BDFIP2526 (2)'!$G$9:$G$1229,SMALL(IF($AO$6='BDFIP2526 (2)'!$D$9:$D$1229,ROW('BDFIP2526 (2)'!$D$9:$D$1229)-MIN(ROW($D$9))+1,""),ROWS(AS$12:AS17))),"")} | AT17: {=IFERROR(INDEX('BDFIP2526 (2)'!$F$9:$F$1229,SMALL(IF($AO$6='BDFIP2526 (2)'!$D$9:$D$1229,ROW('BDFIP2526 (2)'!$D$9:$D$1229)-MIN(ROW($D$9))+1,""),ROWS(AT$12:AT17))),"")} | AU17: {=IFERROR(INDEX('BDFIP2526 (2)'!$N$9:$N$1229,SMALL(IF($AO$6='BDFIP2526 (2)'!$D$9:$D$1229,ROW('BDFIP2526 (2)'!$D$9:$D$1229)-MIN(ROW($D$9))+1,""),ROWS(AU$12:AU17))),"")} | AV17: {=IFERROR(INDEX('BDFIP2526 (2)'!$M$9:$M$1229,SMALL(IF($AO$6='BDFIP2526 (2)'!$D$9:$D$1229,ROW('BDFIP2526 (2)'!$D$9:$D$1229)-MIN(ROW($D$9))+1,""),ROWS(AV$12:AV17))),"")} | AW17: {=IFERROR(INDEX('BDFIP2526 (2)'!$E$9:$E$1229,SMALL(IF($AO$6='BDFIP2526 (2)'!$D$9:$D$1229,ROW('BDFIP2526 (2)'!$D$9:$D$1229)-MIN(ROW($D$9))+1,""),ROWS(AW$12:AW17))),"")} | AX17: {=IFERROR(INDEX('BDFIP2526 (2)'!#REF!,SMALL(IF($AO$6='BDFIP2526 (2)'!$D$9:$D$1229,ROW('BDFIP2526 (2)'!$D$9:$D$1229)-MIN(ROW($D$9))+1,""),ROWS(AX$12:AX17))),"")} | AY17: {=IFERROR(INDEX('BDFIP2526 (2)'!$J$9:$J$1229,SMALL(IF($AO$6='BDFIP2526 (2)'!$D$9:$D$1229,ROW('BDFIP2526 (2)'!$D$9:$D$1229)-MIN(ROW($D$9))+1,""),ROWS(AY$12:AY17))),"")} | AZ17: {=IFERROR(INDEX('BDFIP2526 (2)'!$K$9:$K$1229,SMALL(IF($AO$6='BDFIP2526 (2)'!$D$9:$D$1229,ROW('BDFIP2526 (2)'!$D$9:$D$1229)-MIN(ROW($D$9))+1,""),ROWS(AZ$12:AZ17))),"")} | BA17: {=IFERROR(INDEX(#REF!,SMALL(IF($AO$6='BDFIP2526 (2)'!$D$9:$D$1229,ROW('BDFIP2526 (2)'!$D$9:$D$1229)-MIN(ROW($D$9))+1,""),ROWS(BA$12:BA17))),"")}
B18: 10 | C18: PL051 | D18: MULUNDA KABASELE | E18: 6515 | F18: M | G18: 7°EB | H18: PY | I18: Aout | J18: 25 | L18: N | M18: VEND | N18: 45898 | O18: 2025-2026 | P18: SEC | Q18: 832970855 | AO18: =SMALL($AQ$11:$AQ$16,5) -> 6 | AS18: {=IFERROR(INDEX('BDFIP2526 (2)'!$G$9:$G$1229,SMALL(IF($AO$6='BDFIP2526 (2)'!$D$9:$D$1229,ROW('BDFIP2526 (2)'!$D$9:$D$1229)-MIN(ROW($D$9))+1,""),ROWS(AS$12:AS18))),"")} | AT18: {=IFERROR(INDEX('BDFIP2526 (2)'!$F$9:$F$1229,SMALL(IF($AO$6='BDFIP2526 (2)'!$D$9:$D$1229,ROW('BDFIP2526 (2)'!$D$9:$D$1229)-MIN(ROW($D$9))+1,""),ROWS(AT$12:AT18))),"")} | AU18: {=IFERROR(INDEX('BDFIP2526 (2)'!$N$9:$N$1229,SMALL(IF($AO$6='BDFIP2526 (2)'!$D$9:$D$1229,ROW('BDFIP2526 (2)'!$D$9:$D$1229)-MIN(ROW($D$9))+1,""),ROWS(AU$12:AU18))),"")} | AV18: {=IFERROR(INDEX('BDFIP2526 (2)'!$M$9:$M$1229,SMALL(IF($AO$6='BDFIP2526 (2)'!$D$9:$D$1229,ROW('BDFIP2526 (2)'!$D$9:$D$1229)-MIN(ROW($D$9))+1,""),ROWS(AV$12:AV18))),"")} | AW18: {=IFERROR(INDEX('BDFIP2526 (2)'!$E$9:$E$1229,SMALL(IF($AO$6='BDFIP2526 (2)'!$D$9:$D$1229,ROW('BDFIP2526 (2)'!$D$9:$D$1229)-MIN(ROW($D$9))+1,""),ROWS(AW$12:AW18))),"")} | AX18: {=IFERROR(INDEX('BDFIP2526 (2)'!#REF!,SMALL(IF($AO$6='BDFIP2526 (2)'!$D$9:$D$1229,ROW('BDFIP2526 (2)'!$D$9:$D$1229)-MIN(ROW($D$9))+1,""),ROWS(AX$12:AX18))),"")} | AY18: {=IFERROR(INDEX('BDFIP2526 (2)'!$J$9:$J$1229,SMALL(IF($AO$6='BDFIP2526 (2)'!$D$9:$D$1229,ROW('BDFIP2526 (2)'!$D$9:$D$1229)-MIN(ROW($D$9))+1,""),ROWS(AY$12:AY18))),"")} | AZ18: {=IFERROR(INDEX('BDFIP2526 (2)'!$K$9:$K$1229,SMALL(IF($AO$6='BDFIP2526 (2)'!$D$9:$D$1229,ROW('BDFIP2526 (2)'!$D$9:$D$1229)-MIN(ROW($D$9))+1,""),ROWS(AZ$12:AZ18))),"")} | BA18: {=IFERROR(INDEX(#REF!,SMALL(IF($AO$6='BDFIP2526 (2)'!$D$9:$D$1229,ROW('BDFIP2526 (2)'!$D$9:$D$1229)-MIN(ROW($D$9))+1,""),ROWS(BA$12:BA18))),"")}
B19: 11 | C19: PL070 | D19: KUMWIMBA ILUNGA | E19: 6518 | F19: M | G19: 8°EB | H19: PY | I19: Sept | L19: N | M19: VEND | N19: 45898 | O19: 2025-2026 | P19: SEC | Q19: 977415665 | AO19: =SMALL($AQ$11:$AQ$16,3) -> 2 | AS19: {=IFERROR(INDEX('BDFIP2526 (2)'!$G$9:$G$1229,SMALL(IF($AO$6='BDFIP2526 (2)'!$D$9:$D$1229,ROW('BDFIP2526 (2)'!$D$9:$D$1229)-MIN(ROW($D$9))+1,""),ROWS(AS$12:AS19))),"")} | AT19: {=IFERROR(INDEX('BDFIP2526 (2)'!$F$9:$F$1229,SMALL(IF($AO$6='BDFIP2526 (2)'!$D$9:$D$1229,ROW('BDFIP2526 (2)'!$D$9:$D$1229)-MIN(ROW($D$9))+1,""),ROWS(AT$12:AT19))),"")} | AU19: {=IFERROR(INDEX('BDFIP2526 (2)'!$N$9:$N$1229,SMALL(IF($AO$6='BDFIP2526 (2)'!$D$9:$D$1229,ROW('BDFIP2526 (2)'!$D$9:$D$1229)-MIN(ROW($D$9))+1,""),ROWS(AU$12:AU19))),"")} | AV19: {=IFERROR(INDEX('BDFIP2526 (2)'!$M$9:$M$1229,SMALL(IF($AO$6='BDFIP2526 (2)'!$D$9:$D$1229,ROW('BDFIP2526 (2)'!$D$9:$D$1229)-MIN(ROW($D$9))+1,""),ROWS(AV$12:AV19))),"")} | AW19: {=IFERROR(INDEX('BDFIP2526 (2)'!$E$9:$E$1229,SMALL(IF($AO$6='BDFIP2526 (2)'!$D$9:$D$1229,ROW('BDFIP2526 (2)'!$D$9:$D$1229)-MIN(ROW($D$9))+1,""),ROWS(AW$12:AW19))),"")} | AX19: {=IFERROR(INDEX('BDFIP2526 (2)'!#REF!,SMALL(IF($AO$6='BDFIP2526 (2)'!$D$9:$D$1229,ROW('BDFIP2526 (2)'!$D$9:$D$1229)-MIN(ROW($D$9))+1,""),ROWS(AX$12:AX19))),"")} | AY19: {=IFERROR(INDEX('BDFIP2526 (2)'!$J$9:$J$1229,SMALL(IF($AO$6='BDFIP2526 (2)'!$D$9:$D$1229,ROW('BDFIP2526 (2)'!$D$9:$D$1229)-MIN(ROW($D$9))+1,""),ROWS(AY$12:AY19))),"")} | AZ19: {=IFERROR(INDEX('BDFIP2526 (2)'!$K$9:$K$1229,SMALL(IF($AO$6='BDFIP2526 (2)'!$D$9:$D$1229,ROW('BDFIP2526 (2)'!$D$9:$D$1229)-MIN(ROW($D$9))+1,""),ROWS(AZ$12:AZ19))),"")} | BA19: {=IFERROR(INDEX(#REF!,SMALL(IF($AO$6='BDFIP2526 (2)'!$D$9:$D$1229,ROW('BDFIP2526 (2)'!$D$9:$D$1229)-MIN(ROW($D$9))+1,""),ROWS(BA$12:BA19))),"")}
B20: 12 | C20: LT404 | D20: AMBOAKA MATAMBA | E20: 6166 | F20: F | G20: 3°P | H20: PY | I20: Ac.Juin | J20: 17.5 | L20: N | M20: VEND | N20: 45905 | O20: 2025-2026 | P20: PRM
B21: 13 | C21: LT403 | D21: MULUMBA MATAMBA | E21: 6163 | F21: M | G21: 4°P | H21: PY | I21: Juin | J21: 35 | L21: N | M21: VEND | N21: 45905 | O21: 2025-2026 | P21: PRM
B22: 14 | C22: PL658 | D22: KABASU MPIANA | E22: 6605 | F22: M | G22: 2°HP | H22: PY | I22: Sept | J22: 45 | L22: N | M22: MERC | N22: 45931 | O22: 2025-2026 | P22: SEC
B23: 15 | C23: PL541 | D23: NEHEMA KAZADI | E23: 6606 | F23: F | G23: 2°Lit | H23: PY | I23: Sld.Sept | J23: 25 | L23: A | M23: MERC | N23: 45931 | O23: 2025-2026 | P23: SEC | Q23: 0831515793/0975956926
B24: 16 | C24: LT519 | D24: MUSWAYA KATAY Baraka | E24: 6607 | F24: M | G24: 1M | H24: PY | I24: Sept | J24: 40 | L24: N | M24: MERC | N24: 45931 | O24: 2025-2026 | P24: MAT | Q24: 993573914
B25: 17 | C25: LT508 | D25: MUTOMBO KISIMBA | E25: 6608 | F25: F | G25: 2M | H25: PY | I25: Sept | J25: 40 | L25: N | M25: MERC | N25: 45931 | O25: 2025-2026 | P25: MAT | Q25: 992347717
B26: 18 | C26: LT539 | D26: ZUBENDA AMISI | E26: 6609 | F26: M | G26: 3°P | H26: PY | I26: Sld.Sept | J26: 20 | L26: N | M26: MERC | N26: 45931 | O26: 2025-2026 | P26: PRM | Q26: 990095123
B27: 19 | C27: LT539 | D27: ZUBENDA AMISI | E27: 6610 | F27: M | G27: 3°P | H27: PY | I27: Oct | J27: 40 | L27: N | M27: MERC | N27: 45931 | O27: 2025-2026 | P27: PRM | Q27: 990095123
B28: 20 | C28: LT539 | D28: ZUBENDA AMISI | E28: 6611 | F28: M | G28: 3°P | H28: PY | I28: Nov | J28: 40 | L28: N | M28: MERC | N28: 45931 | O28: 2025-2026 | P28: PRM | Q28: 990095123
B29: 21 | C29: LT498 | D29: AMISI KYANGA | E29: 6615 | F29: M | G29: 1°P | H29: PY | I29: Oct | J29: 40 | L29: N | M29: MERC | N29: 45931 | O29: 2025-2026 | P29: PRM | Q29: 810174897
B30: 22 | C30: LT498 | D30: AMISI KYANGA | E30: 6616 | F30: M | G30: 1°P | H30: PY | I30: Nov | J30: 40 | L30: N | M30: MERC | N30: 45931 | O30: 2025-2026 | P30: PRM | Q30: 810174897
B31: 23 | C31: LT511 | D31: SHILO AMISI KYANDA | E31: 6617 | F31: F | G31: 1M | H31: PY | I31: Oct | J31: 40 | L31: N | M31: MERC | N31: 45931 | O31: 2025-2026 | P31: MAT | Q31: 810174897
B32: 24 | C32: LT511 | D32: SHILO AMISI KYANDA | E32: 6618 | F32: F | G32: 1M | H32: PY | I32: Ac.Nov | J32: 10 | L32: N | M32: MERC | N32: 45931 | O32: 2025-2026 | P32: MAT | Q32: 810174897
B33: 25 | C33: LT552 | D33: TSHISHIMBI MUBENGA | E33: 6619 | F33: M | G33: 3M | H33: PY | I33: Sept | J33: 40 | L33: N | M33: MERC | N33: 45931 | O33: 2025-2026 | P33: MAT | Q33: 0990480162/0990312395
B34: 26 | C34: LT315 | D34: KAPAFULE KAPENGA | E34: 6620 | F34: M | G34: 5°P | H34: PY | I34: Sept | J34: 40 | L34: N | M34: MERC | N34: 45931 | O34: 2025-2026 | P34: PRM
B35: 27 | C35: LT314 | D35: KAPENGA KAPENGA | E35: 6621 | F35: M | G35: 3°P | H35: PY | I35: Sept | J35: 40 | L35: N | M35: MERC | N35: 45931 | O35: 2025-2026 | P35: PRM
B36: 28 | C36: LT509 | D36: NGOYI KAPENGA esther | E36: 6623 | F36: F | G36: 2M | H36: PY | I36: Sept | J36: 40 | L36: N | M36: MERC | N36: 45931 | O36: 2025-2026 | P36: MAT
B37: 29 | C37: PL134 | D37: NANA BERNARD | E37: 6624 | F37: F | G37: 3°CG | H37: PY | I37: Sept | J37: 55 | L37: N | M37: MERC | N37: 45931 | O37: 2025-2026 | P37: SEC | Q37: 972432203
B38: 30 | C38: LT347 | D38: SHAMY NALUNDA | E38: 6625 | F38: F | G38: 1°P | H38: PY | I38: Sept | J38: 40 | L38: A | M38: MERC | N38: 45931 | O38: 2025-2026 | P38: PRM | Q38: 0970669499/0976860674
B39: 31 | C39: PL370 | D39: KABONGO MULUMBA | E39: 6626 | F39: M | G39: 4°EL | H39: PY | I39: Sept | J39: 80 | L39: A | M39: MERC | N39: 45931 | O39: 25-26 | P39: SEC | Q39: 814001138
B40: 32 | C40: LT395 | D40: KASONGO KIZIBA | E40: 6627 | F40: M | G40: 1°P | I40: Sept | J40: 40 | L40: A | M40: MERC | N40: 45931 | O40: 2025-2026 | P40: PRM
B41: 33 | C41: LT079 | D41: KASONGO KIZIBA OWEN | E41: 6628 | F41: M | G41: 5°P | H41: PY | I41: Sept | J41: 40 | L41: A | M41: MERC | N41: 45931 | O41: 2025-2026 | P41: PRM | Q41: 813002370
B42: 34 | C42: PL519 | D42: KASONGO KIZIBA | E42: 6629 | F42: F | G42: 1°EL | H42: PY | I42: Sept | J42: 55 | L42: A | M42: MERC | N42: 45931 | O42: 2025-2026 | P42: SEC | Q42: 903180516
B43: 35 | C43: LT163 | D43: OKITO SAMBA | E43: 6630 | F43: M | G43: 4°P | H43: PY | I43: Sept | J43: 40 | L43: A | M43: MERC | N43: 45931 | O43: 2025-2026 | P43: PRM | Q43: 999159905
B44: 36 | C44: LT164 | D44: OKOMBO SAMBA | E44: 6631 | F44: M | G44: 2°P | H44: PY | I44: Sept | J44: 40 | L44: A | M44: MERC | N44: 45931 | O44: 2025-2026 | P44: PRM | Q44: 999159905
B45: 37 | C45: LT494 | D45: LUBANGI SAMBA | E45: 6632 | F45: M | G45: 2M | H45: PY | I45: Sept | J45: 40 | L45: A | M45: MERC | N45: 45931 | O45: 2025-2026 | P45: MAT | Q45: 999159905
B46: 38 | C46: PL227 | D46: MUMBA KALIMA | E46: 6633 | F46: F | G46: 4°HP | H46: PY | I46: Sept | J46: 80 | L46: N | M46: JEUD | N46: 45932 | O46: 25-26 | P46: SEC | Q46: 979340056
...
